Workbook

Sheet Roteirização
A1: nome | B1: lat | C1: lng | D1: tipo | E1: descricao | F1: cep | G1: rota
A2: {=_xlfn.UNIQUE(Prog!E1:E924)} -> DESTINATARIO
A3: United Auto Nagoya Comercio De Veiculos | B3: =IFERROR(_xlfn.XLOOKUP(F3,BASE!F:F,BASE!B:B),"") -> -23.567631 | C3: =IFERROR(_xlfn.XLOOKUP(F3,BASE!F:F,BASE!C:C),"") -> -46.498993 | D3: =IFERROR(VLOOKUP(A3,BASE!A:D,4,),"") -> amarelo | E3: =IFERROR(_xlfn.XLOOKUP(F3,Prog!J:J,Prog!A:A),"") -> AUTO 801 | F3: =IFERROR(VLOOKUP(A3,Prog!E:J,6,0),"") -> 03527-000 | G3: =E3 -> AUTO 801
A4: Fernanda Serafim | B4: =IFERROR(_xlfn.XLOOKUP(F4,BASE!F:F,BASE!B:B),"") -> -23.659373121649352 | C4: =IFERROR(_xlfn.XLOOKUP(F4,BASE!F:F,BASE!C:C),"") -> -46.70699828890128 | D4: =IFERROR(VLOOKUP(A4,BASE!A:D,4,),"") -> aquamarine | E4: =IFERROR(_xlfn.XLOOKUP(F4,Prog!J:J,Prog!A:A),"") -> Rota 23 | F4: =IFERROR(VLOOKUP(A4,Prog!E:J,6,0),"") -> 04746-110 | G4: =E4 -> Rota 23
A5: Maq Ville Pecas E Servicos Ltda | B5: =IFERROR(_xlfn.XLOOKUP(F5,BASE!F:F,BASE!B:B),"") -> -23.575035178332552 | C5: =IFERROR(_xlfn.XLOOKUP(F5,BASE!F:F,BASE!C:C),"") -> -46.70773153308379 | D5: =IFERROR(VLOOKUP(A5,BASE!A:D,4,),"") -> aquamarine | E5: =IFERROR(_xlfn.XLOOKUP(F5,Prog!J:J,Prog!A:A),"") -> Rota 34 | F5: =IFERROR(VLOOKUP(A5,Prog!E:J,6,0),"") -> 05510-001 | G5: =E5 -> Rota 34
A6: Tabata Fernandes | B6: =IFERROR(_xlfn.XLOOKUP(F6,BASE!F:F,BASE!B:B),"") -> -23.51453189363787 | C6: =IFERROR(_xlfn.XLOOKUP(F6,BASE!F:F,BASE!C:C),"") -> -46.716306704249874 | D6: =IFERROR(VLOOKUP(A6,BASE!A:D,4,),"") -> aquamarine | E6: =IFERROR(_xlfn.XLOOKUP(F6,Prog!J:J,Prog!A:A),"") -> Rota 31 | F6: =IFERROR(VLOOKUP(A6,Prog!E:J,6,0),"") -> 05092-000 | G6: =E6 -> Rota 31
A7: 227392 - Pbkids Brinquedos - Grupo RH | B7: =IFERROR(_xlfn.XLOOKUP(F7,BASE!F:F,BASE!B:B),"") -> -23.68303895291024 | C7: =IFERROR(_xlfn.XLOOKUP(F7,BASE!F:F,BASE!C:C),"") -> -46.55811628308023 | D7: =IFERROR(VLOOKUP(A7,BASE!A:D,4,),"") -> azul | E7: =IFERROR(_xlfn.XLOOKUP(F7,Prog!J:J,Prog!A:A),"") -> AGENDA 16 | F7: =IFERROR(VLOOKUP(A7,Prog!E:J,6,0),"") -> 09726-252 | G7: =E7 -> AGENDA 16
A8: Art Walk - B. Perdizes | B8: =IFERROR(_xlfn.XLOOKUP(F8,BASE!F:F,BASE!B:B),"") -> -23.527801 | C8: =IFERROR(_xlfn.XLOOKUP(F8,BASE!F:F,BASE!C:C),"") -> -46.680122 | D8: =IFERROR(VLOOKUP(A8,BASE!A:D,4,),"") -> verde | E8: =IFERROR(_xlfn.XLOOKUP(F8,Prog!J:J,Prog!A:A),"") -> Rota 31 | F8: =IFERROR(VLOOKUP(A8,Prog!E:J,6,0),"") -> 05005-900 | G8: =E8 -> Rota 31
A9: Sapiens - Consultoria De Marketing | B9: =IFERROR(_xlfn.XLOOKUP(F9,BASE!F:F,BASE!B:B),"") -> -23.565286730918853 | C9: =IFERROR(_xlfn.XLOOKUP(F9,BASE!F:F,BASE!C:C),"") -> -46.70550650424805 | D9: =IFERROR(VLOOKUP(A9,BASE!A:D,4,),"") -> aquamarine | E9: =IFERROR(_xlfn.XLOOKUP(F9,Prog!J:J,Prog!A:A),"") -> Rota 34 | F9: =IFERROR(VLOOKUP(A9,Prog!E:J,6,0),"") -> 05505-040 | G9: =E9 -> Rota 34
A10: Afeet - Bourdon | B10: =IFERROR(_xlfn.XLOOKUP(F10,BASE!F:F,BASE!B:B),"") -> -23.528044 | C10: =IFERROR(_xlfn.XLOOKUP(F10,BASE!F:F,BASE!C:C),"") -> -46.679591 | D10: =IFERROR(VLOOKUP(A10,BASE!A:D,4,),"") -> azul | E10: =IFERROR(_xlfn.XLOOKUP(F10,Prog!J:J,Prog!A:A),"") -> P 7000 | F10: =IFERROR(VLOOKUP(A10,Prog!E:J,6,0),"") -> 05005-030 | G10: =E10 -> P 7000
A11: COMPANHIA BRASILEIRA DE DISTRIBUICAO AUTOMOTIVA S.A | B11: =IFERROR(_xlfn.XLOOKUP(F11,BASE!F:F,BASE!B:B),"") -> -23.63916589883055 | C11: =IFERROR(_xlfn.XLOOKUP(F11,BASE!F:F,BASE!C:C),"") -> -46.58871662241577 | D11: =IFERROR(VLOOKUP(A11,BASE!A:D,4,),"") -> aquamarine | E11: =IFERROR(_xlfn.XLOOKUP(F11,Prog!J:J,Prog!A:A),"") -> AGENDA 13 | F11: =IFERROR(VLOOKUP(A11,Prog!E:J,6,0),"") -> 04185-160 | G11: =E11 -> AGENDA 13
A12: Unimed S J Campos Coop Trab Medico | B12: =IFERROR(_xlfn.XLOOKUP(F12,BASE!F:F,BASE!B:B),"") -> -23.207377454339365 | C12: =IFERROR(_xlfn.XLOOKUP(F12,BASE!F:F,BASE!C:C),"") -> -45.890709779127114 | D12: =IFERROR(VLOOKUP(A12,BASE!A:D,4,),"") -> rosa | E12: =IFERROR(_xlfn.XLOOKUP(F12,Prog!J:J,Prog!A:A),"") -> LS Rota 44 R | F12: =IFERROR(VLOOKUP(A12,Prog!E:J,6,0),"") -> 12245-481 | G12: =E12 -> LS Rota 44 R
A13: Veder Do Brasil Eireli | B13: =IFERROR(_xlfn.XLOOKUP(F13,BASE!F:F,BASE!B:B),"") -> -23.587884560262292 | C13: =IFERROR(_xlfn.XLOOKUP(F13,BASE!F:F,BASE!C:C),"") -> -46.56033373308334 | D13: =IFERROR(VLOOKUP(A13,BASE!A:D,4,),"") -> aquamarine | E13: =IFERROR(_xlfn.XLOOKUP(F13,Prog!J:J,Prog!A:A),"") -> Rota 26 | F13: =IFERROR(VLOOKUP(A13,Prog!E:J,6,0),"") -> 03223-110 | G13: =E13 -> Rota 26
A14: MEDMOGI MED ORTOPEDICOS SUZANMED | B14: =IFERROR(_xlfn.XLOOKUP(F14,BASE!F:F,BASE!B:B),"") -> -23.521340768495453 | C14: =IFERROR(_xlfn.XLOOKUP(F14,BASE!F:F,BASE!C:C),"") -> -46.19190497541355 | D14: =IFERROR(VLOOKUP(A14,BASE!A:D,4,),"") -> rosa | E14: =IFERROR(_xlfn.XLOOKUP(F14,Prog!J:J,Prog!A:A),"") -> LS Rota 45 | F14: =IFERROR(VLOOKUP(A14,Prog!E:J,6,0),"") -> 08710-160 | G14: =E14 -> LS Rota 45
... A22: Fuad Said Madi | B22: =IFERROR(_xlfn.XLOOKUP(F22,BASE!F:F,BASE!B:B),"") -> -23.985227156080423 | C22: =IFERROR(_xlfn.XLOOKUP(F22,BASE!F:F,BASE!C:C),"") -> -46.26565963039967 | D22: =IFERROR(VLOOKUP(A22,BASE!A:D,4,),"") -> aquamarine | E22: =IFERROR(_xlfn.XLOOKUP(F22,Prog!J:J,Prog!A:A),"") -> Rota 36 | F22: =IFERROR(VLOOKUP(A22,Prog!E:J,6,0),"") -> 11460-000 | G22: =E22 -> Rota 36
A23: Rialan Litoral Comercio De Autopecas Ltda | B23: =IFERROR(_xlfn.XLOOKUP(F23,BASE!F:F,BASE!B:B),"") -> -23.92234353524191 | C23: =IFERROR(_xlfn.XLOOKUP(F23,BASE!F:F,BASE!C:C),"") -> -46.409254213560125 | D23: aquamarine | E23: =IFERROR(_xlfn.XLOOKUP(F23,Prog!J:J,Prog!A:A),"") -> Rota 37 | F23: =IFERROR(VLOOKUP(A23,Prog!E:J,6,0),"") -> 11533-040 | G23: =E23 -> Rota 37
A24: Sampa Motors Ltda | B24: =IFERROR(_xlfn.XLOOKUP(F24,BASE!F:F,BASE!B:B),"") -> -23.502341 | C24: =IFERROR(_xlfn.XLOOKUP(F24,BASE!F:F,BASE!C:C),"") -> -46.707005 | D24: =IFERROR(VLOOKUP(A24,BASE!A:D,4,),"") -> amarelo | E24: =IFERROR(_xlfn.XLOOKUP(F24,Prog!J:J,Prog!A:A),"") -> H 701 DHL | F24: =IFERROR(VLOOKUP(A24,Prog!E:J,6,0),"") -> 02924-000 | G24: =E24 -> H 701 DHL
A25: Ascendant Comercio De Veiculos Ltda | B25: =IFERROR(_xlfn.XLOOKUP(F25,BASE!F:F,BASE!B:B),"") -> -23.670316375710623 | C25: =IFERROR(_xlfn.XLOOKUP(F25,BASE!F:F,BASE!C:C),"") -> -46.70282054657272 | D25: =IFERROR(VLOOKUP(A25,BASE!A:D,4,),"") -> amarelo | E25: =IFERROR(_xlfn.XLOOKUP(F25,Prog!J:J,Prog!A:A),"") -> H 703 | F25: =IFERROR(VLOOKUP(A25,Prog!E:J,6,0),"") -> 04795-100 | G25: =E25 -> H 703
A26: Cmd Automoveis Ltda Honda Forte | B26: =IFERROR(_xlfn.XLOOKUP(F26,BASE!F:F,BASE!B:B),"") -> -23.518109 | C26: =IFERROR(_xlfn.XLOOKUP(F26,BASE!F:F,BASE!C:C),"") -> -46.60896 | D26: =IFERROR(VLOOKUP(A26,BASE!A:D,4,),"") -> amarelo | E26: =IFERROR(_xlfn.XLOOKUP(F26,Prog!J:J,Prog!A:A),"") -> H 702 | F26: =IFERROR(VLOOKUP(A26,Prog!E:J,6,0),"") -> 02054-050 | G26: =E26 -> H 702
A27: Cmd Automoveis Ltda | B27: =IFERROR(_xlfn.XLOOKUP(F27,BASE!F:F,BASE!B:B),"") -> -23.536423 | C27: =IFERROR(_xlfn.XLOOKUP(F27,BASE!F:F,BASE!C:C),"") -> -46.73163 | D27: =IFERROR(VLOOKUP(A27,BASE!A:D,4,),"") -> amarelo | E27: =IFERROR(_xlfn.XLOOKUP(F27,Prog!J:J,Prog!A:A),"") -> H 705 | F27: =IFERROR(VLOOKUP(A27,Prog!E:J,6,0),"") -> 05314-001 | G27: =E27 -> H 705
A28: Abc Motors Ltda | B28: =IFERROR(_xlfn.XLOOKUP(F28,BASE!F:F,BASE!B:B),"") -> -23.613868 | C28: =IFERROR(_xlfn.XLOOKUP(F28,BASE!F:F,BASE!C:C),"") -> -46.577669 | D28: =IFERROR(VLOOKUP(A28,BASE!A:D,4,),"") -> amarelo | E28: =IFERROR(_xlfn.XLOOKUP(F28,Prog!J:J,Prog!A:A),"") -> H 700 | F28: =IFERROR(VLOOKUP(A28,Prog!E:J,6,0),"") -> 09521-040 | G28: =E28 -> H 700
A29: United Auto Nagoya Com De Veiculos | B29: =IFERROR(_xlfn.XLOOKUP(F29,BASE!F:F,BASE!B:B),"") -> -23.612776338449073 | C29: =IFERROR(_xlfn.XLOOKUP(F29,BASE!F:F,BASE!C:C),"") -> -46.72955481513777 | D29: =IFERROR(VLOOKUP(A29,BASE!A:D,4,),"") -> amarelo | E29: =IFERROR(_xlfn.XLOOKUP(F29,Prog!J:J,Prog!A:A),"") -> H 708 | F29: =IFERROR(VLOOKUP(A29,Prog!E:J,6,0),"") -> 05724-001 | G29: =E29 -> H 708
A30: Daitan Comercio De Veiculos Ltda | B30: =IFERROR(_xlfn.XLOOKUP(F30,BASE!F:F,BASE!B:B),"") -> -23.625027927116182 | C30: =IFERROR(_xlfn.XLOOKUP(F30,BASE!F:F,BASE!C:C),"") -> -46.64018410424612 | D30: =IFERROR(VLOOKUP(A30,BASE!A:D,4,),"") -> amarelo | E30: =IFERROR(_xlfn.XLOOKUP(F30,Prog!J:J,Prog!A:A),"") -> H 703 | F30: =IFERROR(VLOOKUP(A30,Prog!E:J,6,0),"") -> 04045-004 | G30: =E30 -> H 703
A31: Sp Japan Motors Dist.De Veics.Ltda | B31: =IFERROR(_xlfn.XLOOKUP(F31,BASE!F:F,BASE!B:B),"") -> -23.567817 | C31: =IFERROR(_xlfn.XLOOKUP(F31,BASE!F:F,BASE!C:C),"") -> -46.612498 | D31: =IFERROR(VLOOKUP(A31,BASE!A:D,4,),"") -> amarelo | E31: =IFERROR(_xlfn.XLOOKUP(F31,Prog!J:J,Prog!A:A),"") -> H 706 JAPAN | F31: =IFERROR(VLOOKUP(A31,Prog!E:J,6,0),"") -> 01524-000 | G31: =E31 -> H 706 JAPAN
A32: United Auto Nagoya Ltda | B32: =IFERROR(_xlfn.XLOOKUP(F32,BASE!F:F,BASE!B:B),"") -> -23.66013710875708 | C32: =IFERROR(_xlfn.XLOOKUP(F32,BASE!F:F,BASE!C:C),"") -> -46.53102105024517 | D32: =IFERROR(VLOOKUP(A32,BASE!A:D,4,),"") -> amarelo | E32: =IFERROR(_xlfn.XLOOKUP(F32,Prog!J:J,Prog!A:A),"") -> H 700 | F32: =IFERROR(VLOOKUP(A32,Prog!E:J,6,0),"") -> 09040-160 | G32: =E32 -> H 700
A33: Sp Japan Motors Distribuidora De Veiculos Ltda | B33: =IFERROR(_xlfn.XLOOKUP(F33,BASE!F:F,BASE!B:B),"") -> -23.545485 | C33: =IFERROR(_xlfn.XLOOKUP(F33,BASE!F:F,BASE!C:C),"") -> -46.556715 | D33: =IFERROR(VLOOKUP(A33,BASE!A:D,4,),"") -> amarelo | E33: =IFERROR(_xlfn.XLOOKUP(F33,Prog!J:J,Prog!A:A),"") -> H 706 JAPAN | F33: =IFERROR(VLOOKUP(A33,Prog!E:J,6,0),"") -> 03321-001 | G33: =E33 -> H 706 JAPAN
A34: United Auto Nagoya Com.Veiculos Ltda | B34: =IFERROR(_xlfn.XLOOKUP(F34,BASE!F:F,BASE!B:B),"") -> -23.672905528157607 | C34: =IFERROR(_xlfn.XLOOKUP(F34,BASE!F:F,BASE!C:C),"") -> -46.56919917726045 | D34: =IFERROR(VLOOKUP(A34,BASE!A:D,4,),"") -> amarelo | E34: =IFERROR(_xlfn.XLOOKUP(F34,Prog!J:J,Prog!A:A),"") -> H 700 | F34: =IFERROR(VLOOKUP(A34,Prog!E:J,6,0),"") -> 09609-000 | G34: =E34 -> H 700
A35: Sp Japan Motors Distrib. De Veic. L | B35: =IFERROR(_xlfn.XLOOKUP(F35,BASE!F:F,BASE!B:B),"") -> -23.588675 | C35: =IFERROR(_xlfn.XLOOKUP(F35,BASE!F:F,BASE!C:C),"") -> -46.62045 | D35: =IFERROR(VLOOKUP(A35,BASE!A:D,4,),"") -> amarelo | E35: =IFERROR(_xlfn.XLOOKUP(F35,Prog!J:J,Prog!A:A),"") -> H 706 JAPAN | F35: =IFERROR(VLOOKUP(A35,Prog!E:J,6,0),"") -> 04260-000 | G35: =E35 -> H 706 JAPAN
... A137: Notre Dame Intermedica Saude S.A | B137: =IFERROR(_xlfn.XLOOKUP(F137,BASE!F:F,BASE!B:B),"") -> -23.69201996578947 | C137: =IFERROR(_xlfn.XLOOKUP(F137,BASE!F:F,BASE!C:C),"") -> -46.55586744657212 | D137: =IFERROR(VLOOKUP(A137,BASE!A:D,4,),"") -> rosa | E137: =IFERROR(_xlfn.XLOOKUP(F137,Prog!J:J,Prog!A:A),"") -> LS Rota 49 | F137: =IFERROR(VLOOKUP(A137,Prog!E:J,6,0),"") -> 09750-660 | G137: =E137 -> LS Rota 49
A138: Notre Dame Intermedica S.A | B138: =IFERROR(_xlfn.XLOOKUP(F138,BASE!F:F,BASE!B:B),"") -> -23.682014746595915 | C138: =IFERROR(_xlfn.XLOOKUP(F138,BASE!F:F,BASE!C:C),"") -> -46.54302456191632 | D138: =IFERROR(VLOOKUP(A138,BASE!A:D,4,),"") -> rosa | E138: LS Rota 49 | F138: =IFERROR(VLOOKUP(A138,Prog!E:J,6,0),"") -> 09751-000 | G138: =E138 -> LS Rota 49
A139: ASSOCIACAO FUNDO DE INCENTIVO A PESQUISA | B139: =IFERROR(_xlfn.XLOOKUP(F139,BASE!F:F,BASE!B:B),"") -> -23.76640933366652 | C139: =IFERROR(_xlfn.XLOOKUP(F139,BASE!F:F,BASE!C:C),"") -> -46.58650636084093 | D139: =IFERROR(VLOOKUP(A139,BASE!A:D,4,),"") -> rosa | E139: =IFERROR(_xlfn.XLOOKUP(F139,Prog!J:J,Prog!A:A),"") -> LS Rota 49 | F139: =IFERROR(VLOOKUP(A139,Prog!E:J,6,0),"") -> 09843-400 | G139: =E139 -> LS Rota 49
A140: Ph 7 Comercio E Rep De Prod P Diag Ltda | B140: =IFERROR(_xlfn.XLOOKUP(F140,BASE!F:F,BASE!B:B),"") -> -23.560491217411833 | C140: =IFERROR(_xlfn.XLOOKUP(F140,BASE!F:F,BASE!C:C),"") -> -46.68737096192091 | D140: =IFERROR(VLOOKUP(A140,BASE!A:D,4,),"") -> rosa | E140: =IFERROR(_xlfn.XLOOKUP(F140,Prog!J:J,Prog!A:A),"") -> LS Rota 49 | F140: =IFERROR(VLOOKUP(A140,Prog!E:J,6,0),"") -> 09715-130 | G140: =E140 -> LS Rota 49
A141: Prevent Senior Atendimento A Saude | B141: =IFERROR(_xlfn.XLOOKUP(F141,BASE!F:F,BASE!B:B),"") -> -23.664829859746778 | C141: =IFERROR(_xlfn.XLOOKUP(F141,BASE!F:F,BASE!C:C),"") -> -46.56914878890099 | D141: =IFERROR(VLOOKUP(A141,BASE!A:D,4,),"") -> rosa | E141: =IFERROR(_xlfn.XLOOKUP(F141,Prog!J:J,Prog!A:A),"") -> LS Rota 49 | F141: =IFERROR(VLOOKUP(A141,Prog!E:J,6,0),"") -> 09611-000 | G141: =E141 -> LS Rota 49
A142: Rede D Or Sao Luiz Sa | B142: =IFERROR(_xlfn.XLOOKUP(F142,BASE!F:F,BASE!B:B),"") -> -23.71353493160424 | C142: =IFERROR(_xlfn.XLOOKUP(F142,BASE!F:F,BASE!C:C),"") -> -46.41962998889959 | D142: =IFERROR(VLOOKUP(A142,BASE!A:D,4,),"") -> rosa | E142: =IFERROR(_xlfn.XLOOKUP(F142,Prog!J:J,Prog!A:A),"") -> LS Rota 49 | F142: =IFERROR(VLOOKUP(A142,Prog!E:J,6,0),"") -> 09424-080 | G142: =E142 -> LS Rota 49
A143: Instituto Hermes Pardini Sa | B143: =IFERROR(_xlfn.XLOOKUP(F143,BASE!F:F,BASE!B:B),"") -> -23.49644469789858 | C143: =IFERROR(_xlfn.XLOOKUP(F143,BASE!F:F,BASE!C:C),"") -> -46.626185943998955 | D143: =IFERROR(VLOOKUP(A143,BASE!A:D,4,),"") -> rosa | E143: =IFERROR(_xlfn.XLOOKUP(F143,Prog!J:J,Prog!A:A),"") -> LS Rota 47 | F143: =IFERROR(VLOOKUP(A143,Prog!E:J,6,0),"") -> 02401-100 | G143: =E143 -> LS Rota 47
A144: Intermedica Sist Saude Sa | B144: =IFERROR(_xlfn.XLOOKUP(F144,BASE!F:F,BASE!B:B),"") -> -23.51177688494652 | C144: =IFERROR(_xlfn.XLOOKUP(F144,BASE!F:F,BASE!C:C),"") -> -46.58379049458572 | D144: =IFERROR(VLOOKUP(A144,BASE!A:D,4,),"") -> rosa | E144: =IFERROR(_xlfn.XLOOKUP(F144,Prog!J:J,Prog!A:A),"") -> LS Rota 47 | F144: =IFERROR(VLOOKUP(A144,Prog!E:J,6,0),"") -> 02122-080 | G144: =E144 -> LS Rota 47
A145: Prevent Senior Private Operadora De Saud | B145: =IFERROR(_xlfn.XLOOKUP(F145,BASE!F:F,BASE!B:B),"") -> -23.61683160790286 | C145: =IFERROR(_xlfn.XLOOKUP(F145,BASE!F:F,BASE!C:C),"") -> -46.702064068620885 | D145: =IFERROR(VLOOKUP(A145,BASE!A:D,4,),"") -> rosa | E145: =IFERROR(_xlfn.XLOOKUP(F145,Prog!J:J,Prog!A:A),"") -> LS Rota 50 | F145: =IFERROR(VLOOKUP(A145,Prog!E:J,6,0),"") -> 05686-902 | G145: =E145 -> LS Rota 50
A146: Prevent Senior Private Operadora De Saude Ltda | B146: =IFERROR(_xlfn.XLOOKUP(F146,BASE!F:F,BASE!B:B),"") -> -23.564057297540263 | C146: =IFERROR(_xlfn.XLOOKUP(F146,BASE!F:F,BASE!C:C),"") -> -46.59164659075597 | D146: =IFERROR(VLOOKUP(A146,BASE!A:D,4,),"") -> rosa | E146: =IFERROR(_xlfn.XLOOKUP(F146,Prog!J:J,Prog!A:A),"") -> LS Rota 42 R | F146: =IFERROR(VLOOKUP(A146,Prog!E:J,6,0),"") -> 03119-010 | G146: =E146 -> LS Rota 42 R
A147: Casa De Saude Santa Marcelina | B147: =IFERROR(_xlfn.XLOOKUP(F147,BASE!F:F,BASE!B:B),"") -> -23.56482055963156 | C147: =IFERROR(_xlfn.XLOOKUP(F147,BASE!F:F,BASE!C:C),"") -> -46.42308993123234 | D147: =IFERROR(VLOOKUP(A147,BASE!A:D,4,),"") -> rosa | E147: =IFERROR(_xlfn.XLOOKUP(F147,Prog!J:J,Prog!A:A),"") -> LS Rota 42 R | F147: =IFERROR(VLOOKUP(A147,Prog!E:J,6,0),"") -> 08270-070 | G147: =E147 -> LS Rota 42 R
A148: Laboratorios Clinicos Associados Lt | B148: =IFERROR(_xlfn.XLOOKUP(F148,BASE!F:F,BASE!B:B),"") -> -23.635912029907733 | C148: =IFERROR(_xlfn.XLOOKUP(F148,BASE!F:F,BASE!C:C),"") -> -46.66305065623297 | D148: =IFERROR(VLOOKUP(A148,BASE!A:D,4,),"") -> rosa | E148: =IFERROR(_xlfn.XLOOKUP(F148,Prog!J:J,Prog!A:A),"") -> LS Rota 50 | F148: =IFERROR(VLOOKUP(A148,Prog!E:J,6,0),"") -> 04633-000 | G148: =E148 -> LS Rota 50
...

Sheet Prog
A1: ROTA | B1: APELIDO_TOMADOR | C1: NOTAFISCAL | D1: SERIENF | E1: DESTINATARIO | F1: EXIGE_AGENDAMENTO | G1: CNPJDESTINATARIO | H1: UF_ENTREGA | I1: MUNICIPIO_ENTREGA | J1: CEPENTREGA | K1: REDESPACHANTE | L1: DATA_PREVISAO | M1: DATA | N1: EXISTE_AGENDAMENTO | O1: DATAAGENDAMENTO | P1: ULTIMAOCORRENCIA | Q1: DATAOCORRENCIA | R1: OBSERVACAOOCORRENCIA | S1: KEY | T1: DEVOLUCAO | U1: KEY_NOTA | V1: FILIAL_DESTINO | W1: SETOR | X1: NUMEROPEDIDOK | Y1: TIPOITEM | Z1: FILIAL_ORIGEM | AA1: STATUS_POR_NOTA | AB1: VALOR_NF | AC1: VOLUMES | AD1: PESOCUBADO | AE1: CHAVE_NFE | AF1: DATA_CTE | AG1: CTE_RPS | AH1: INICIO_VIAGEM | AI1: REMETENTE | AJ1: TIPO_VIAGEM | AK1: ULTIMAVIAGEM | AL1: CHAVENFE | AM1: STATUSPRAZO | AN1: REGIAOCEPENTREGA | AO1: OPERACAO | AP1: CNPJ_REMETENTE | AQ1: DATA_CHEGADA_FILIAL_DESTINO | AR1: COD_OCORRENCIA | AS1: CHEGADAEFETIVAULTTRANSFERENCIA | AT1: DATAPODIMAGEM | AU1: CNPJ_TOMADOR | AV1: UF_TOMADOR | AW1: MUNICIPIO_TOMADOR | AX1: LOGRADOURO_TOMADOR | AY1: CEP_TOMADOR | AZ1: BAIRRO_TOMADOR | BA1: NOME_TOMADOR | BB1: BAIRRO | BC1: CHAVE_CTE | BD1: TIPO_PRODUTO | BE1: REMETENTEORIGEM | BF1: TIPO_SERVICO | BG1: EXIGEAGENDAMENTO_CONTRATO | BH1: CODIGO_AGENDAMENTO | BI1: DATAEMISSAONF | BJ1: CEP_ENTREGA | BK1: FILIAL_ATUAL | BL1: CHAVE_CLIENTE | BM1: PESO_CONSIDERADO | BN1: PESO_TOTAL | BO1: DATA_ENTREGA | BP1: NUMERO_AGENDAMENTO | BQ1: FILIAL_ENTREGA | BR1: CARRIER_CODE | BS1: STATUS_CTE | BT1: VENCIMENTO_PERECIVEL | BU1: ENDERECOENTREGA | BV1: ROTA_VIAGEM | BW1: STATUS_VIAGEM | BX1: DATAINCLUSAO_AGENDAMENTO | BY1: HOUVE_PLANEJAMENTO | BZ1: TOTAL_OCORRENCIAS_PLANEJAMENTO | CA1: DATA_ULTIMO_PLANEJAMENTO | CB1: FILIAL_ORIGEM_SIGLA | CC1: FILIAL_ATUAL_SIGLA | CD1: FILIAL_DESTINO_SIGLA | CE1: FILIAL_LAST_MILE | CF1: SIGLA_LAST_MILE
A2: AUTO 801 | B2: HONDA AUTOMOVEIS BRASIL LTDA | C2: 5830198 | D2: 0 | E2: United Auto Nagoya Comercio De Veiculos | F2: - | G2: 03.962.539/0001-10 | H2: SP | I2: São Paulo | J2: 03527-000 | K2: BELAFRAN TRANSPORTES LTDA | L2: 46072.566 | M2: BACKLOG | N2: N | P2: PLANEJADO | Q2: 46216.971 | R2: PLANEJADO PARA O DIA 14/07/202613/07/2026 23:31:47 - seg | S2: 245433840 | T2: Não | U2: 2026/191151-156-5830198-0 | V2: PA - LOGISTICA REVERSA DOX - JANDIRA - SP | W2: AEMCE | Y2: Perigoso | Z2: PA - HONDA AUTOMOVEIS - SUMARE - SP | AA2: Aguardando Transferência | AB2: 744.11 | AC2: 1 | AD2: 7.965 | AE2: 35260201192333000394550000058301981284777106 | AF2: 46071.566 | AG2: 48601 | AH2: 46077.478 | AI2: HONDA AUTOMOVEIS BRASIL LTDA | AJ2: Transferência | AK2: 2026/191151-156 | AL2: 35260201192333000394550000058301981284777106 | AM2: Maior que 30 | AN2: 35 | AO2: Outbound | AP2: 01.192.333/0003-94 | AQ2: 46077 | AR2: 700 | AS2: 46077.7 | AU2: 01.192.333/0003-94 | AV2: SP | AW2: Sumaré | AX2: Municipal Valencio Calegari | AY2: 13181-903 | AZ2: Nova Veneza | BA2: HONDA AUTOMOVEIS DO BRASIL LTDA | BB2: Vila Matilde | BC2: 35260200233065000187572100000486011000486010 | BD2: Perigoso | BE2: HONDA AUTOMOVEIS DO BRASIL LTDA | BF2: 4 | BG2: Não | BI2: 46071 | BJ2: 03527-000 | BK2: PA - LOGISTICA REVERSA DOX - JANDIRA - SP | BM2: 1.77 | BN2: 1.77 | BQ2: PA - FILIAL SPG - GUARULHOS - SP | BS2: Aguardando Transferência | BU2: Aricanduva,5555 | BW2: Finalizada | BY2: SIM | BZ2: 34 | CA2: 2026-07-13 23:18:00.0 | CB2: HON | CC2: CEL LR | CD2: CEL LR | CE2: PA - FILIAL SPG - GUARULHOS - SP | CF2: SPG
A3: Rota 23 | B3: BEAUTY LABS COSMETICOS LTDA | C3: 184834 | D3: 10 | E3: Fernanda Serafim | F3: - | G3: 409.363.738-57 | H3: SP | I3: São Paulo | J3: 04746-110 | L3: 46134.808 | M3: BACKLOG | N3: N | P3: PLANEJADO | Q3: 46216.971 | R3: PLANEJADO PARA O DIA 14/07/202613/07/2026 23:33:03 - seg | S3: 249539775 | T3: Não | U3: -184834-10 | W3: RETAIL | Z3: PA - DFN - BARUERI - SP | AA3: Aguardando Transferência | AB3: 143.85 | AC3: 1 | AD3: 0.5197 | AE3: 35260432306307000292550100001848341525098917 | AF3: 46132.808 | AG3: 45164 | AI3: BEAUTY LABS COSMETICOS LTDA | AL3: 35260432306307000292550100001848341525098917 | AM3: Maior que 30 | AN3: 47 | AO3: Outbound | AP3: 32.306.307/0002-92 | AR3: 700 | AU3: 32.306.307/0002-92 | AV3: SP | AW3: Barueri | AX3: Dos Alpes | AY3: 06423-080 | AZ3: Jardim Belval | BA3: Beauty Labs Cosmeticos Ltda | BB3: Santo Amaro | BC3: 35260400233065000187571760000451641000451643 | BE3: Beauty Labs Cosmeticos Ltda | BF3: 4 | BG3: Não | BI3: 46129 | BJ3: 04746-110 | BK3: PA - DFN - BARUERI - SP | BL3: 2026_205630 | BM3: 0.51972 | BN3: 0.426 | BQ3: PA - FILIAL SPG - GUARULHOS - SP | BS3: Aguardando Transferência | BU3: Benedito Fernandes,152 | BY3: SIM | BZ3: 47 | CA3: 2026-07-13 23:18:00.0 | CB3: DFN | CC3: DFN | CE3: PA - FILIAL SPG - GUARULHOS - SP | CF3: SPG
A4: Rota 34 | B4: WHIRLPOOL S.A | C4: 10642956 | D4: 1 | E4: Maq Ville Pecas E Servicos Ltda | F4: - | G4: 71.856.942/0001-14 | H4: SP | I4: São Paulo | J4: 05510-001 | K4: TATIANE MARIA DE JESUS | L4: 46146.406 | M4: BACKLOG | N4: N | P4: PLANEJADO | Q4: 46216.971 | R4: PLANEJADO PARA O DIA 14/07/202613/07/2026 23:33:04 - seg | S4: 250191378 | T4: Não | U4: 2026/384029-62-10642956-1 | W4: TECHNOLOGY | Z4: PA - WHIRLPOOL - SÃO PAULO - SP | AA4: Em Elaboração | AB4: 22.03 | AC4: 6 | AD4: 0.2995 | AE4: 35260459105999002804550010106429561187222875 | AF4: 46142.406 | AG4: 30018 | AH4: 46142.407 | AI4: WHIRLPOOL S.A | AJ4: Lotação | AK4: 2026/384029-62 | AL4: 35260459105999002804550010106429561187222875 | AM4: Maior que 30 | AN4: 55 | AO4: Outbound | AP4: 59.105.999/0028-04 | AQ4: 46142 | AR4: 700 | AT4: 46142 | AU4: 59.105.999/0028-04 | AV4: SP | AW4: São Paulo | AX4: Olympia Semeraro | AY4: 04183-090 | AZ4: JARDIM SANTA EMILIA | BA4: Whirlpool S.A | BB4: Butanta | BE4: Whirlpool S.A | BF4: 3 | BG4: Não | BI4: 46142 | BJ4: 05510-001 | BK4: PA - WHIRLPOOL - SÃO PAULO - SP | BL4: 0556480750 | BM4: 0.07 | BN4: 0.07 | BQ4: PA - FILIAL SPG - GUARULHOS - SP | BR4: 0254250932 | BS4: Concluído Parcialmente | BU4: Sapetuba,57 | BW4: Finalizada | BY4: SIM | BZ4: 40 | CA4: 2026-07-13 23:18:00.0 | CB4: BAR | CC4: BAR | CE4: PA - FILIAL SPG - GUARULHOS - SP | CF4: SPG
A5: Rota 31 | B5: BELEZE & OLIVEIRA - COMERCIO DE COSMETICOS LTDA | C5: 132706 | D5: 10 | E5: Tabata Fernandes | F5: - | G5: 056.158.905-41 | H5: SP | I5: São Paulo | J5: 05092-000 | L5: 46182.548 | M5: BACKLOG | N5: N | P5: PLANEJADO | Q5: 46216.971 | R5: PLANEJADO PARA O DIA 14/07/202613/07/2026 23:33:04 - seg | S5: 252266550 | T5: Não | U5: -132706-10 | W5: RETAIL | Z5: PA - DFN - SERRA - ES | AA5: Aguardando Transferência | AB5: 268.2 | AC5: 1 | AD5: 1.0224 | AE5: 32260517616018000468550100001327061239585659 | AF5: 46176.548 | AG5: 77466 | AI5: BELEZE & OLIVEIRA - COMERCIO DE COSMETICOS LTDA | AL5: 32260517616018000468550100001327061239585659 | AM5: Maior que 30 | AN5: 50 | AO5: Outbound | AP5: 17.616.018/0004-68 | AR5: 700 | AU5: 17.616.018/0004-68 | AV5: ES | AW5: Serra | AX5: Comendador Roberto Ugolini | AY5: 29168-022 | AZ5: Civit I | BA5: Beleze Oliveira - Comercio De Cosmeticos Ltda | BB5: Vila Anastacio | BC5: 32260600233065002392572380000774661000774661 | BE5: Beleze Oliveira - Comercio De Cosmeticos Ltda | BF5: 4 | BG5: Não | BI5: 46173 | BJ5: 05092-000 | BK5: PA - HUB CEL - SP - DOX 1000 | BM5: 1.02236 | BN5: 0.838 | BQ5: PA - FILIAL SPG - GUARULHOS - SP | BS5: Aguardando Transferência | BU5: Bartolomeu Paes,292 | BY5: SIM | BZ5: 23 | CA5: 2026-07-13 23:18:00.0 | CB5: CADASTRAR | CC5: CEL H | CE5: PA - FILIAL SPG - GUARULHOS - SP | CF5: SPG
A6: AGENDA 16 | B6: HASBRO DO BRASIL INDUSTRIA E COMERCIO DE BRINQUEDOS E JOGOS LTDA | C6: 26779 | D6: 1 | E6: 227392 - Pbkids Brinquedos - Grupo RH | F6: - | G6: 64.731.433/0065-64 | H6: SP | I6: São Bernardo do Campo | J6: 09726-252 | K6: KLEBER COMITRE | L6: 46189.458 | M6: BACKLOG | N6: S | O6: 46189.458 | P6: REPROGRAMADO PARA | Q6: 46216.746 | R6: agendado para dia 15/07/26 - 09:00 às 11:0013/07/2026 17 | S6: 252621332 | T6: Não | U6: 2026/547322-337-26779-1 | V6: PA - FILIAL SPG - GUARULHOS - SP | W6: CONSUMER | Z6: PA - STARLINK(SPACEX) - EXTREMA - MG | AA6: Aguardando Redistribuição | AB6: 5553.91 | AC6: 26 | AD6: 105 | AE6: 31260608743754000496550010000267791582093750 | AF6: 46183.528 | AG6: 259496 | AH6: 46189.075 | AI6: HASBRO DO BRASIL INDUSTRIA E COMERCIO DE BRINQUEDOS E JOGOS LTDA | AJ6: Entrega | AK6: 2026/547322-337 | AL6: 31260608743754000496550010000267791582093750 | AM6: Entre 16 e 30 | AN6: 97 | AO6: Outbound | AP6: 08.743.754/0004-96 | AQ6: 46189 | AR6: 152 | AS6: 46184.031 | AU6: 08.743.754/0004-96 | AV6: MG | AW6: Extrema | AX6: Municipal Luiz Lopes Neto | AY6: 37645-050 | AZ6: Distrito Industrial Tenentes | BA6: Hasbro Do Brasil Ind Com Brinq Ltda | BB6: Vila Marlene | BC6: 31260600233065004255572170002594961002594962 | BE6: Hasbro Do Brasil Ind Com Brinq Ltda | BF6: 4 | BG6: Sim | BH6: 1596881 | BI6: 46181 | BJ6: 09726-252 | BK6: PA - FILIAL SPG - GUARULHOS - SP | BM6: 105 | BN6: 34.08 | BP6: 2026/167336-1 | BQ6: PA - FILIAL SPG - GUARULHOS - SP | BS6: Aguardando Redistribuição | BU6: Kennedy,700 | BV6: AGENDA 23 | BW6: Finalizada | BX6: 15/06/2026 08:15:00 | BY6: SIM | BZ6: 1 | CA6: 2026-06-15 21:06:00.0 | CB6: CADASTRAR | CC6: SPG | CD6: SPG | CE6: PA - FILIAL SPG - GUARULHOS - SP | CF6: SPG
A7: AGENDA 16 | B7: HASBRO DO BRASIL INDUSTRIA E COMERCIO DE BRINQUEDOS E JOGOS LTDA | C7: 26780 | D7: 1 | E7: 227392 - Pbkids Brinquedos - Grupo RH | F7: - | G7: 64.731.433/0065-64 | H7: SP | I7: São Bernardo do Campo | J7: 09726-252 | K7: KLEBER COMITRE | L7: 46189.458 | M7: BACKLOG | N7: S | O7: 46189.458 | P7: REPROGRAMADO PARA | Q7: 46216.746 | R7: agendado para dia 15/07/26 - 09:00 às 11:0013/07/2026 17 | S7: 252621335 | T7: Não | U7: 2026/547322-337-26780-1 | V7: PA - FILIAL SPG - GUARULHOS - SP | W7: CONSUMER | Z7: PA - STARLINK(SPACEX) - EXTREMA - MG | AA7: Aguardando Redistribuição | AB7: 347.94 | AC7: 1 | AD7: 3 | AE7: 31260608743754000496550010000267801491492946 | AF7: 46183.528 | AG7: 259496 | AH7: 46189.075 | AI7: HASBRO DO BRASIL INDUSTRIA E COMERCIO DE BRINQUEDOS E JOGOS LTDA | AJ7: Entrega | AK7: 2026/547322-337 | AL7: 31260608743754000496550010000267801491492946 | AM7: Entre 16 e 30 | AN7: 97 | AO7: Outbound | AP7: 08.743.754/0004-96 | AQ7: 46189 | AR7: 152 | AS7: 46184.031 | AU7: 08.743.754/0004-96 | AV7: MG | AW7: Extrema | AX7: Municipal Luiz Lopes Neto | AY7: 37645-050 | AZ7: Distrito Industrial Tenentes | BA7: Hasbro Do Brasil Ind Com Brinq Ltda | BB7: Vila Marlene | BC7: 31260600233065004255572170002594961002594962 | BE7: Hasbro Do Brasil Ind Com Brinq Ltda | BF7: 4 | BG7: Sim | BH7: 1596881 | BI7: 46181 | BJ7: 09726-252 | BK7: PA - FILIAL SPG - GUARULHOS - SP | BM7: 3 | BN7: 1.77 | BP7: 2026/167336-1 | BQ7: PA - FILIAL SPG - GUARULHOS - SP | BS7: Aguardando Redistribuição | BU7: Kennedy,700 | BV7: AGENDA 23 | BW7: Finalizada | BX7: 15/06/2026 08:15:00 | BY7: SIM | BZ7: 1 | CA7: 2026-06-15 21:06:00.0 | CB7: CADASTRAR | CC7: SPG | CD7: SPG | CE7: PA - FILIAL SPG - GUARULHOS - SP | CF7: SPG
A8: AGENDA 16 | B8: HASBRO DO BRASIL INDUSTRIA E COMERCIO DE BRINQUEDOS E JOGOS LTDA | C8: 26991 | D8: 1 | E8: 227392 - Pbkids Brinquedos - Grupo RH | F8: - | G8: 64.731.433/0065-64 | H8: SP | I8: São Bernardo do Campo | J8: 09726-252 | K8: KLEBER COMITRE | L8: 46189.458 | M8: BACKLOG | N8: S | O8: 46189.458 | P8: REPROGRAMADO PARA | Q8: 46216.746 | R8: agendado para dia 15/07/26 - 09:00 às 11:0013/07/2026 17 | S8: 252621338 | T8: Não | U8: 2026/547322-337-26991-1 | V8: PA - FILIAL SPG - GUARULHOS - SP | W8: CONSUMER | Z8: PA - STARLINK(SPACEX) - EXTREMA - MG | AA8: Aguardando Redistribuição | AB8: 8592.09 | AC8: 38 | AD8: 183 | AE8: 31260608743754000496550010000269911225504282 | AF8: 46183.528 | AG8: 259496 | AH8: 46189.075 | AI8: HASBRO DO BRASIL INDUSTRIA E COMERCIO DE BRINQUEDOS E JOGOS LTDA | AJ8: Entrega | AK8: 2026/547322-337 | AL8: 31260608743754000496550010000269911225504282 | AM8: Entre 16 e 30 | AN8: 97 | AO8: Outbound | AP8: 08.743.754/0004-96 | AQ8: 46189 | AR8: 152 | AS8: 46184.031 | AU8: 08.743.754/0004-96 | AV8: MG | AW8: Extrema | AX8: Municipal Luiz Lopes Neto | AY8: 37645-050 | AZ8: Distrito Industrial Tenentes | BA8: Hasbro Do Brasil Ind Com Brinq Ltda | BB8: Vila Marlene | BC8: 31260600233065004255572170002594961002594962 | BE8: Hasbro Do Brasil Ind Com Brinq Ltda | BF8: 4 | BG8: Sim | BH8: 1596881 | BI8: 46181 | BJ8: 09726-252 | BK8: PA - FILIAL SPG - GUARULHOS - SP | BM8: 183 | BN8: 64.54 | BP8: 2026/167336-1 | BQ8: PA - FILIAL SPG - GUARULHOS - SP | BS8: Aguardando Redistribuição | BU8: Kennedy,700 | BV8: AGENDA 23 | BW8: Finalizada | BX8: 15/06/2026 08:15:00 | BY8: SIM | BZ8: 1 | CA8: 2026-06-15 21:06:00.0 | CB8: CADASTRAR | CC8: SPG | CD8: SPG | CE8: PA - FILIAL SPG - GUARULHOS - SP | CF8: SPG
A9: Rota 31 | B9: PREMIER | C9: 255276 | D9: 1 | E9: Art Walk - B. Perdizes | F9: - | G9: 05.055.599/0020-47 | H9: SP | I9: São Paulo | J9: 05005-900 | L9: 46206.25 | M9: BACKLOG | N9: N | P9: SOBRA DE MERCADORIA SEM NOTA FISCAL | Q9: 46206.739 | R9: sobra03/07/2026 21:08:14 - sex - GISBATIS - PA - FILIAL | S9: 253919668 | T9: Não | U9: -255276-1 | W9: RETAIL | X9: 0109691966 | Z9: PA - PREMIER (FÍSIA - NIKE) - EXTREMA - MG | AA9: Aguardando Transferência | AB9: 852.79 | AC9: 1 | AD9: 16.5006 | AE9: 31260609098221000623550010002552761500774833 | AF9: 46203.891 | AG9: 124639 | AI9: PREMIER | AL9: 31260609098221000623550010002552761500774833 | AM9: Entre 6 e 15 | AN9: 50 | AO9: Outbound | AP9: 09.098.221/0006-23 | AR9: 82 | AU9: 09.098.221/0006-23 | AV9: MG | AW9: Extrema | AX9: Municipal Luiz Lopes Neto | AY9: 37645-906 | AZ9: Distrito Industrial Tenentes | BA9: Premier Dist De Vestuarios Calcados Equipamentos E Acessorio | BB9: Perdizes | BC9: 31260600233065004255572010001246391001246396 | BE9: Premier Dist De Vestuarios Calcados Equipamentos E Acessorio | BF9: 4 | BG9: Não | BI9: 46203 | BJ9: 05005-900 | BK9: PA - PREMIER (FÍSIA - NIKE) - EXTREMA - MG | BM9: 16.500619 | BN9: 5.04 | BQ9: PA - FILIAL SPG - GUARULHOS - SP | BS9: Aguardando Transferência | BU9: Palestra Italia,500 | BY9: NÃO | CB9: EXT | CC9: EXT | CE9: PA - FILIAL SPG - GUARULHOS - SP | CF9: SPG
A10: Rota 34 | B10: BEAUTY LABS COSMETICOS LTDA | C10: 216964 | D10: 10 | E10: Sapiens - Consultoria De Marketing | F10: - | G10: 08.159.942/0001-29 | H10: SP | I10: São Paulo | J10: 05505-040 | L10: 46209.511 | M10: BACKLOG | N10: N | P10: PLANEJADO | Q10: 46216.971 | R10: PLANEJADO PARA O DIA 14/07/202613/07/2026 23:33:05 - seg | S10: 254014482 | T10: Não | U10: -216964-10 | W10: RETAIL | Z10: PA - DFN - BARUERI - SP | AA10: Aguardando Transferência | AB10: 41.93 | AC10: 1 | AD10: 3.9284 | AE10: 35260632306307000292550100002169641377426375 | AF10: 46206.511 | AG10: 102403 | AI10: BEAUTY LABS COSMETICOS LTDA | AL10: 35260632306307000292550100002169641377426375 | AM10: Entre 6 e 15 | AN10: 55 | AO10: Outbound | AP10: 32.306.307/0002-92 | AR10: 700 | AU10: 32.306.307/0002-92 | AV10: SP | AW10: Barueri | AX10: Dos Alpes | AY10: 06423-080 | AZ10: Jardim Belval | BA10: Beauty Labs Cosmeticos Ltda | BB10: Butanta | BC10: 35260700233065000187571760001024031001024036 | BE10: Beauty Labs Cosmeticos Ltda | BF10: 4 | BG10: Não | BI10: 46202 | BJ10: 05505-040 | BK10: PA - DFN - BARUERI - SP | BL10: 2026_372351 | BM10: 3.9284 | BN10: 3.22 | BQ10: PA - FILIAL SPG - GUARULHOS - SP | BS10: Aguardando Transferência | BU10: Professor Horacio Berlinck,30 | BY10: SIM | BZ10: 7 | CA10: 2026-07-13 23:18:00.0 | CB10: DFN | CC10: DFN | CE10: PA - FILIAL SPG - GUARULHOS - SP | CF10: SPG
A11: P 7000 | B11: PREMIER | C11: 253283 | D11: 1 | E11: Afeet - Bourdon | F11: - | G11: 05.055.599/0029-85 | H11: SP | I11: São Paulo | J11: 05005-030 | K11: UNIDOCK'S ASSESSORIA E LOGISTICA DE MATERIAIS LTD | L11: 46210.997 | M11: BACKLOG | N11: S | O11: 46210.997 | P11: PLANEJADO | Q11: 46216.971 | R11: PLANEJADO PARA O DIA 14/07/202613/07/2026 23:29:36 - seg | S11: 253880575 | T11: Não | U11: 2026/616905-337-253283-1 | V11: PA - FILIAL SPG - GUARULHOS - SP | W11: RETAIL | X11: 0109740910 | Z11: PA - PREMIER (FÍSIA - NIKE) - EXTREMA - MG | AA11: Aguardando Redistribuição | AB11: 568.53 | AC11: 1 | AD11: 12.2977 | AE11: 31260609098221000623550010002532831499835760 | AF11: 46203.634 | AG11: 124060 | AH11: 46206.26 | AI11: PREMIER | AJ11: Entrega | AK11: 2026/616905-337 | AL11: 31260609098221000623550010002532831499835760 | AM11: Entre 6 e 15 | AN11: 50 | AO11: Outbound | AP11: 09.098.221/0006-23 | AQ11: 46209 | AR11: 700 | AS11: 46203.881 | AU11: 09.098.221/0006-23 | AV11: MG | AW11: Extrema | AX11: Municipal Luiz Lopes Neto | AY11: 37645-906 | AZ11: Distrito Industrial Tenentes | BA11: Premier Dist De Vestuarios Calcados Equipamentos E Acessorio | BB11: Perdizes | BC11: 31260600233065004255572010001240601001240607 | BE11: Premier Dist De Vestuarios Calcados Equipamentos E Acessorio | BF11: 4 | BG11: Não | BH11: 1624033 | BI11: 46201 | BJ11: 05005-030 | BK11: PA - FILIAL SPG - GUARULHOS - SP | BM11: 12.297675 | BN11: 3.36 | BP11: 2026/194550-1 | BQ11: PA - FILIAL SPG - GUARULHOS - SP | BS11: Aguardando Redistribuição | BU11: Palestra Italia,500 | BV11: P 903 | BW11: Aguardando Finalização | BX11: 03/07/2026 10:36:46 | BY11: SIM | BZ11: 1 | CA11: 2026-07-13 23:18:00.0
A12: Rota 31 | B12: PREMIER | C12: 253283 | D12: 1 | E12: Afeet - Bourdon | F12: - | G12: 05.055.599/0029-85 | H12: SP | I12: São Paulo | J12: 05005-030 | K12: UNIDOCK'S ASSESSORIA E LOGISTICA DE MATERIAIS LTD | L12: 46210.997 | M12: BACKLOG | N12: S | O12: 46210.997 | P12: PLANEJADO | Q12: 46216.971 | R12: PLANEJADO PARA O DIA 14/07/202613/07/2026 23:29:36 - seg | S12: 253880575 | T12: Não | U12: 2026/616905-337-253283-1 | V12: PA - FILIAL SPG - GUARULHOS - SP | W12: RETAIL | X12: 0109740910 | Z12: PA - PREMIER (FÍSIA - NIKE) - EXTREMA - MG | AA12: Aguardando Redistribuição | AB12: 568.53 | AC12: 1 | AD12: 12.2977 | AE12: 31260609098221000623550010002532831499835760 | AF12: 46203.634 | AG12: 124060 | AH12: 46206.26 | AI12: PREMIER | AJ12: Entrega | AK12: 2026/616905-337 | AL12: 31260609098221000623550010002532831499835760 | AM12: Entre 6 e 15 | AN12: 50 | AO12: Outbound | AP12: 09.098.221/0006-23 | AQ12: 46209 | AR12: 700 | AS12: 46203.881 | AU12: 09.098.221/0006-23 | AV12: MG | AW12: Extrema | AX12: Municipal Luiz Lopes Neto | AY12: 37645-906 | AZ12: Distrito Industrial Tenentes | BA12: Premier Dist De Vestuarios Calcados Equipamentos E Acessorio | BB12: Perdizes | BC12: 31260600233065004255572010001240601001240607 | BE12: Premier Dist De Vestuarios Calcados Equipamentos E Acessorio | BF12: 4 | BG12: Não | BH12: 1624033 | BI12: 46201 | BJ12: 05005-030 | BK12: PA - FILIAL SPG - GUARULHOS - SP | BM12: 12.297675 | BN12: 3.36 | BP12: 2026/194550-1 | BQ12: PA - FILIAL SPG - GUARULHOS - SP | BS12: Aguardando Redistribuição | BU12: Palestra Italia,500 | BV12: P 903 | BW12: Aguardando Finalização | BX12: 03/07/2026 10:36:46 | BY12: SIM | BZ12: 1 | CA12: 2026-07-13 23:18:00.0 | CB12: EXT | CC12: SPG | CD12: SPG | CE12: PA - FILIAL SPG - GUARULHOS - SP | CF12: SPG
A13: AGENDA 13 | B13: METALURGICA SCHADEK LTDA | C13: 890262 | D13: 1 | E13: COMPANHIA BRASILEIRA DE DISTRIBUICAO AUTOMOTIVA S.A | F13: - | G13: 42.580.092/0029-77 | H13: SP | I13: São Paulo | J13: 04185-160 | K13: VANDERLEY TRANSPORTES EIRELI | L13: 46211 | M13: BACKLOG | N13: N | P13: PROGRAMADO PARA | Q13: 46217.389 | R13: Data inicial de entrega para: 15/07/2026 08:00:00 e data fin | S13: 254121884 | T13: Não | U13: 2026/622628-82-890262-1 | V13: PA - FILIAL SPG - GUARULHOS - SP | W13: AEMCE | Z13: PA - SCHADEK - PORTO FELIZ - SP | AA13: Aguardando Distribuição | AB13: 895.23 | AC13: 1 | AD13: 3.0984 | AE13: 35260760851417000190550010008902621566529990 | AF13: 46206.811 | AG13: 39209 | AH13: 46209.911 | AI13: METALURGICA SCHADEK LTDA | AJ13: Transferência | AK13: 2026/622628-82 | AL13: 35260760851417000190550010008902621566529990 | AM13: Entre 6 e 15 | AN13: 41 | AO13: Outbound | AP13: 60.851.417/0001-90 | AQ13: 46209 | AR13: 91 | AS13: 46209.97 | AU13: 60.851.417/0001-90 | AV13: SP | AW13: Porto Feliz | AX13: Carlos Magalhaes | AY13: 18547-216 | AZ13: Jardim Bela Vista | BA13: METALURGICA SCHADEK LTDA | BB13: Vila Liviero | BC13: 35260700233065000187572110000392091000392093 | BE13: METALURGICA SCHADEK LTDA | BF13: 4 | BG13: Sim | BI13: 46206 | BJ13: 04185-160 | BK13: PA - FILIAL SPG - GUARULHOS - SP | BL13: 0080780361 | BM13: 3.0984 | BN13: 2.582 | BQ13: PA - FILIAL SPG - GUARULHOS - SP | BS13: Aguardando Distribuição | BU13: Eugenio Bellotto,200 | BW13: Finalizada | BY13: NÃO | CB13: CADASTRAR | CC13: SPG | CD13: SPG | CE13: PA - FILIAL SPG - GUARULHOS - SP | CF13: SPG
A14: LS Rota 44 R | B14: CSL BEHRING COMERCIO DE PRODUTOS FARMACEUTICOS LTD | C14: 173 | D14: 103 | E14: Unimed S J Campos Coop Trab Medico | F14: - | G14: 60.214.517/0016-91 | H14: SP | I14: São José dos Campos | J14: 12245-481 | K14: UNIDOCK'S ASSESSORIA E LOGISTICA DE MATERIAIS LTD | L14: 46216.398 | M14: BACKLOG | N14: N | P14: TRANSFERÊNCIA ENTRE HUBS DHL | Q14: 46217.467 | R14: 14/07/2026 11:12:24 - ter - TMSBENNER - Todas as filiais | S14: 254555743 | T14: Não | U14: 2026/651987-337-173-103 | V14: PA - FILIAL GRU - AÉREO - GUARULHOS - SP | W14: LIFE SCIENCE | Z14: PA - MULTI CLIENTES - GUARULHOS - SP | AA14: Em Transferência | AB14: 3955.47 | AC14: 1 | AD14: 32.399 | AE14: 35260700233065004921551030000001731009666644 | AF14: 46213.398 | AG14: 205928 | AH14: 46217.466 | AI14: UNIDOCKS ASSESSORIA E LOGISTICA DE MATERIAIS | AJ14: Transferência | AK14: 2026/651987-337 | AL14: 35260700233065004921551030000001731009666644 | AM14: No Prazo | AN14: 122 | AO14: Outbound | AP14: 00.233.065/0049-21 | AR14: 133 | AS14: 46213.653 | AU14: 62.969.589/0014-02 | AV14: SP | AW14: Barueri | AX14: Ceci | AY14: 06460-120 | AZ14: Centro | BA14: Csl | BB14: Vila Bethania | BC14: 35260700233065000187571710002059281002059284 | BE14: Unidocks Assessoria E Logistica De Materiais Ltda | BF14: 4 | BG14: Não | BI14: 46213 | BJ14: 12245-481 | BK14: PA - FILIAL SPG - GUARULHOS - SP | BM14: 32.399 | BN14: 32.399 | BQ14: PA - FILIAL SPG - GUARULHOS - SP | BR14: 0,1 | BS14: Em Transferência | BU14: Tivoli,336 | BW14: Em Trânsito | BY14: SIM | BZ14: 1 | CA14: 2026-07-10 20:40:00.0 | CB14: GRU | CC14: SPG | CD14: GRU | CE14: PA - FILIAL SPG - GUARULHOS - SP | CF14: SPG
A15: Rota 26 | B15: STECK INDUSTRIA ELETRICA LTDA | C15: 91630 | D15: 3 | E15: Veder Do Brasil Eireli | F15: - | G15: 65.874.968/0001-92 | H15: SP | I15: São Paulo | J15: 03223-110 | K15: GABRIEL PEREIRA SANT ANA DOS SANTOS | L15: 46216.58 | M15: BACKLOG | N15: N | P15: REENTREGA SEM COBRANÇA DO CLIENTE | Q15: 46216.698 | R15: Horario de recebimento: 08 as 17hs fechado para almoço das | S15: 254379109 | T15: Não | U15: 2026/640852-337-91630-3 | V15: PA - FILIAL SPG - GUARULHOS - SP | W15: TECHNOLOGY | Z15: PA - STECK - ARUJA - SP | AA15: Aguardando Redistribuição | AB15: 29965.42 | AC15: 9 | AD15: 188.8596 | AE15: 35260705890658000300550030000916301932044935 | AF15: 46211.58 | AG15: 58135 | AH15: 46213.261 | AI15: STECK INDUSTRIA ELETRICA LTDA | AJ15: Entrega | AK15: 2026/640852-337 | AL15: 35260705890658000300550030000916301932044935 | AM15: No Prazo | AN15: 32 | AO15: Outbound | AP15: 05.890.658/0003-00 | AQ15: 46213 | AR15: 22 | AS15: 46211.706 | AU15: 05.890.658/0003-00 | AV15: SP | AW15: Arujá | AX15: Adilia Barbosa Neves | AY15: 07413-000 | AZ15: Portao | BA15: Steck Industria Eletrica Ltda | BB15: Jardim Independencia | BC15: 35260700233065000187571500000581351000581358 | BE15: Steck Industria Eletrica Ltda | BF15: 4 | BG15: Não | BI15: 46210 | BJ15: 03223-110 | BK15: PA - FILIAL SPG - GUARULHOS - SP | BL15: 092166 | BM15: 188.8596 | BN15: 116.58 | BQ15: PA - FILIAL SPG - GUARULHOS - SP | BS15: Aguardando Redistribuição | BU15: Secundino Domingues,22 | BV15: Rota 42 | BW15: Finalizada | BY15: SIM | BZ15: 1 | CA15: 2026-07-08 19:37:00.0 | CB15: STECK | CC15: SPG | CD15: SPG | CE15: PA - FILIAL SPG - GUARULHOS - SP | CF15: SPG
A16: LS Rota 45 | B16: CONVATEC BRASIL LTDA | C16: 201980 | D16: 1 | E16: MEDMOGI MED ORTOPEDICOS SUZANMED | F16: - | G16: 27.460.051/0001-52 | H16: SP | I16: Mogi das Cruzes | J16: 08710-160 | K16: VANDERLEY TRANSPORTES EIRELI | L16: 46217.698 | M16: BACKLOG | N16: N | P16: PLANEJADO | Q16: 46216.971 | R16: PLANEJADO PARA O DIA 14/07/202613/07/2026 23:31:59 - seg | S16: 254666201 | T16: Não | U16: 2026/651397-82-201980-1 | V16: PA - FILIAL SPG - GUARULHOS - SP | W16: LIFE SCIENCE | Z16: PA - MULTI ORIGENS - JANDIRA - SP | AA16: Distribuído | AB16: 5376.56 | AC16: 3 | AD16: 24.0411 | AE16: 35260709603161000497550010002019801994773254 | AF16: 46216.698 | AG16: 106832 | AI16: CONVATEC BRASIL LTDA | AJ16: Transferência | AK16: 2026/651397-82 | AL16: 35260709603161000497550010002019801994773254 | AM16: No Prazo | AN16: 87 | AO16: Outbound | AP16: 09.603.161/0004-97 | AR16: 700 | AS16: 46216.968 | AU16: 09.603.161/0004-97 | AV16: SP | AW16: Jundiaí | AX16: Francisco Roveri | AY16: 13212-541 | AZ16: Parque Almerinda Pereira Chaves | BA16: Convatec Brasil Ltda | BB16: Centro | BC16: 35260700233065000187571810001068321001068322 | BE16: Convatec Brasil Ltda | BF16: 4 | BG16: Não | BI16: 46213 | BJ16: 08710-160 | BK16: PA - HUB CEL - SP - DOX 1000 | BL16: 32379135 | BM16: 24.04112 | BN16: 9.694 | BQ16: PA - FILIAL SPG - GUARULHOS - SP | BS16: Distribuído | BU16: Barao De Jaceguai,617 | BW16: Em Elaboração | BY16: SIM | BZ16: 1 | CA16: 2026-07-13 23:18:00.0 | CB16: BAR | CC16: CEL H | CD16: SPG | CE16: PA - FILIAL SPG - GUARULHOS - SP | CF16: SPG
A17: LS Rota 44 R | B17: BD | C17: 382379 | D17: 7 | E17: Hapvida Assistencia Medica S A | F17: - | G17: 63.554.067/0302-67 | H17: SP | I17: São José dos Campos | J17: 12245-280 | K17: UILIAN PRAZITO RODRIGUES | L17: 46217.878 | M17: BACKLOG | N17: N | P17: CHEGADA DHL | Q17: 46217.009 | R17: 14/07/2026 00:14:31 - ter - TMSBENNER - Todas as filiais | S17: 254736860 | T17: Não | U17: 2026/644053-58-382379-7 | V17: PA - MEDTRONIC HIAE BD - OSASCO - SP | W17: LIFE SCIENCE | Z17: PA - BECTON DICKISON BECKMAM BOEHRINGER CSL SAMSUNG - ABBOTT- JOINVILLE - SC - ISDIN SC | AA17: Aguardando Transferência | AB17: 624 | AC17: 1 | AD17: 0 | AE17: 42260721551379002141550070003823791308985977 | AF17: 46216.878 | AG17: 52617 | AH17: 46216.891 | AI17: BD | AJ17: Transferência | AK17: 2026/644053-58 | AL17: 42260721551379002141550070003823791308985977 | AM17: No Prazo | AN17: 122 | AO17: Outbound | AP17: 21.551.379/0021-41 | AQ17: 46217 | AR17: 97 | AS17: 46217.008 | AU17: 21.551.379/0021-41 | AV17: SC | AW17: Itajaí | AX17: Ver Germano Luiz Vieira - Armz 3 | AY17: 88316-701 | AZ17: Itaipava | BA17: BECTON DICKINSON INDUSTRIAS CIRURGICAS LTDA | BB17: Jardim Sao Dimas | BC17: 42260700233065002554570510000526171000526179 | BE17: BECTON DICKINSON INDUSTRIAS CIRURGICAS LTDA | BF17: 3 | BG17: Não | BI17: 46216 | BJ17: 12245-280 | BK17: PA - MEDTRONIC HIAE BD - OSASCO - SP | BL17: 6035858019 | BM17: 3.995 | BN17: 3.995 | BQ17: PA - FILIAL SPG - GUARULHOS - SP | BS17: Aguardando Transferência | BU17: Heitor Villa Lobos,2071 | BW17: Finalizada | BY17: NÃO | CB17: JOI | CC17: BAR | CD17: BAR | CE17: PA - FILIAL SPG - GUARULHOS - SP | CF17: SPG
A18: LS Rota 44 R | B18: BD | C18: 382376 | D18: 7 | E18: Hapvida Assistencia Medica S A | F18: - | G18: 63.554.067/0302-67 | H18: SP | I18: São José dos Campos | J18: 12245-280 | K18: UILIAN PRAZITO RODRIGUES | L18: 46217.878 | M18: BACKLOG | N18: N | P18: CHEGADA DHL | Q18: 46217.009 | R18: 14/07/2026 00:14:31 - ter - TMSBENNER - Todas as filiais | S18: 254736866 | T18: Não | U18: 2026/644053-58-382376-7 | V18: PA - MEDTRONIC HIAE BD - OSASCO - SP | W18: LIFE SCIENCE | Z18: PA - BECTON DICKISON BECKMAM BOEHRINGER CSL SAMSUNG - ABBOTT- JOINVILLE - SC - ISDIN SC | AA18: Aguardando Transferência | AB18: 13800 | AC18: 31 | AD18: 0 | AE18: 42260721551379002141550070003823761308876289 | AF18: 46216.878 | AG18: 52623 | AH18: 46216.891 | AI18: BD | AJ18: Transferência | AK18: 2026/644053-58 | AL18: 42260721551379002141550070003823761308876289 | AM18: No Prazo | AN18: 122 | AO18: Outbound | AP18: 21.551.379/0021-41 | AQ18: 46217 | AR18: 97 | AS18: 46217.008 | AU18: 21.551.379/0021-41 | AV18: SC | AW18: Itajaí | AX18: Ver Germano Luiz Vieira - Armz 3 | AY18: 88316-701 | AZ18: Itaipava | BA18: BECTON DICKINSON INDUSTRIAS CIRURGICAS LTDA | BB18: Jardim Sao Dimas | BC18: 42260700233065002554570510000526231000526230 | BE18: BECTON DICKINSON INDUSTRIAS CIRURGICAS LTDA | BF18: 3 | BG18: Não | BI18: 46216 | BJ18: 12245-280 | BK18: PA - MEDTRONIC HIAE BD - OSASCO - SP | BL18: 6035824247 | BM18: 40.26 | BN18: 40.26 | BQ18: PA - FILIAL SPG - GUARULHOS - SP | BS18: Aguardando Transferência | BU18: Heitor Villa Lobos,2071 | BW18: Finalizada | BY18: NÃO | CB18: JOI | CC18: BAR | CD18: BAR | CE18: PA - FILIAL SPG - GUARULHOS - SP | CF18: SPG
A19: LS Rota 44 R | B19: BD | C19: 382378 | D19: 7 | E19: Hapvida Assistencia Medica S A | F19: - | G19: 63.554.067/0302-67 | H19: SP | I19: São José dos Campos | J19: 12245-280 | K19: UILIAN PRAZITO RODRIGUES | L19: 46217.879 | M19: BACKLOG | N19: N | P19: CHEGADA DHL | Q19: 46217.009 | R19: 14/07/2026 00:14:34 - ter - TMSBENNER - Todas as filiais | S19: 254736875 | T19: Não | U19: 2026/644053-58-382378-7 | V19: PA - MEDTRONIC HIAE BD - OSASCO - SP | W19: LIFE SCIENCE | Z19: PA - BECTON DICKISON BECKMAM BOEHRINGER CSL SAMSUNG - ABBOTT- JOINVILLE - SC - ISDIN SC | AA19: Aguardando Transferência | AB19: 2263.22 | AC19: 7 | AD19: 0 | AE19: 42260721551379002141550070003823781308954632 | AF19: 46216.879 | AG19: 52631 | AH19: 46216.891 | AI19: BD | AJ19: Transferência | AK19: 2026/644053-58 | AL19: 42260721551379002141550070003823781308954632 | AM19: No Prazo | AN19: 122 | AO19: Outbound | AP19: 21.551.379/0021-41 | AQ19: 46217 | AR19: 97 | AS19: 46217.008 | AU19: 21.551.379/0021-41 | AV19: SC | AW19: Itajaí | AX19: Ver Germano Luiz Vieira - Armz 3 | AY19: 88316-701 | AZ19: Itaipava | BA19: BECTON DICKINSON INDUSTRIAS CIRURGICAS LTDA | BB19: Jardim Sao Dimas | BC19: 42260700233065002554570510000526311000526313 | BE19: BECTON DICKINSON INDUSTRIAS CIRURGICAS LTDA | BF19: 3 | BG19: Não | BI19: 46216 | BJ19: 12245-280 | BK19: PA - MEDTRONIC HIAE BD - OSASCO - SP | BL19: 6035847321 | BM19: 10.456 | BN19: 10.456 | BQ19: PA - FILIAL SPG - GUARULHOS - SP | BS19: Aguardando Transferência | BU19: Heitor Villa Lobos,2071 | BW19: Finalizada | BY19: NÃO | CB19: JOI | CC19: BAR | CD19: BAR | CE19: PA - FILIAL SPG - GUARULHOS - SP | CF19: SPG
A20: LS Rota 44 R | B20: BD | C20: 382377 | D20: 7 | E20: Hapvida Assistencia Medica S A | F20: - | G20: 63.554.067/0302-67 | H20: SP | I20: São José dos Campos | J20: 12245-280 | K20: UILIAN PRAZITO RODRIGUES | L20: 46217.879 | M20: BACKLOG | N20: N | P20: CHEGADA DHL | Q20: 46217.009 | R20: 14/07/2026 00:14:33 - ter - TMSBENNER - Todas as filiais | S20: 254736892 | T20: Não | U20: 2026/644053-58-382377-7 | V20: PA - MEDTRONIC HIAE BD - OSASCO - SP | W20: LIFE SCIENCE | Z20: PA - BECTON DICKISON BECKMAM BOEHRINGER CSL SAMSUNG - ABBOTT- JOINVILLE - SC - ISDIN SC | AA20: Aguardando Transferência | AB20: 980.15 | AC20: 7 | AD20: 0 | AE20: 42260721551379002141550070003823771308907629 | AF20: 46216.879 | AG20: 52648 | AH20: 46216.891 | AI20: BD | AJ20: Transferência | AK20: 2026/644053-58 | AL20: 42260721551379002141550070003823771308907629 | AM20: No Prazo | AN20: 122 | AO20: Outbound | AP20: 21.551.379/0021-41 | AQ20: 46217 | AR20: 97 | AS20: 46217.008 | AU20: 21.551.379/0021-41 | AV20: SC | AW20: Itajaí | AX20: Ver Germano Luiz Vieira - Armz 3 | AY20: 88316-701 | AZ20: Itaipava | BA20: BECTON DICKINSON INDUSTRIAS CIRURGICAS LTDA | BB20: Jardim Sao Dimas | BC20: 42260700233065002554570510000526481000526485 | BE20: BECTON DICKINSON INDUSTRIAS CIRURGICAS LTDA | BF20: 3 | BG20: Não | BI20: 46216 | BJ20: 12245-280 | BK20: PA - MEDTRONIC HIAE BD - OSASCO - SP | BL20: 6035865505 | BM20: 25.403 | BN20: 25.403 | BQ20: PA - FILIAL SPG - GUARULHOS - SP | BS20: Aguardando Transferência | BU20: Heitor Villa Lobos,2071 | BW20: Finalizada | BY20: NÃO | CB20: JOI | CC20: BAR | CD20: BAR | CE20: PA - FILIAL SPG - GUARULHOS - SP | CF20: SPG
A21: Rota 32 | B21: METALURGICA SCHADEK LTDA | C21: 894437 | D21: 1 | E21: Josecar Distribuidora De Auto Pecas | F21: - | G21: 52.743.275/0010-00 | H21: SP | I21: São Paulo | J21: 02734-000 | K21: VANDERLEY TRANSPORTES EIRELI | L21: 46218 | M21: D0 | N21: N | P21: CHEGADA DHL | Q21: 46213.862 | R21: 10/07/2026 20:42:28 - sex - TMSBENNER - Todas as filiais | S21: 254543302 | T21: Não | U21: 2026/651397-82-894437-1 | V21: PA - FILIAL SPG - GUARULHOS - SP | W21: AEMCE | Z21: PA - SCHADEK - PORTO FELIZ - SP | AA21: Distribuído | AB21: 35.94 | AC21: 1 | AD21: 1.08 | AE21: 35260760851417000190550010008944371226430462 | AF21: 46213.688 | AG21: 41898 | AI21: METALURGICA SCHADEK LTDA | AJ21: Transferência | AK21: 2026/651397-82 | AL21: 35260760851417000190550010008944371226430462 | AM21: No Prazo | AN21: 27 | AO21: Outbound | AP21: 60.851.417/0001-90 | AR21: 97 | AS21: 46213.829 | AU21: 60.851.417/0001-90 | AV21: SP | AW21: Porto Feliz | AX21: Carlos Magalhaes | AY21: 18547-216 | AZ21: Jardim Bela Vista | BA21: METALURGICA SCHADEK LTDA | BB21: Nossa Senhora Do O | BC21: 35260700233065000187572110000418981000418980 | BE21: METALURGICA SCHADEK LTDA | BF21: 4 | BG21: Não | BI21: 46212 | BJ21: 02734-000 | BK21: PA - HUB CEL - SP - DOX 1000 | BL21: 0080790331 | BM21: 1.08 | BN21: 0.9 | BQ21: PA - FILIAL SPG - GUARULHOS - SP | BS21: Distribuído | BU21: Itaberaba,363 | BW21: Em Elaboração | BY21: NÃO | CB21: CADASTRAR | CC21: CEL H | CD21: SPG | CE21: PA - FILIAL SPG - GUARULHOS - SP | CF21: SPG
A22: Rota 30 | B22: METALURGICA SCHADEK LTDA | C22: 892978 | D22: 1 | E22: Tonini Distribuidora Ltda | F22: - | G22: 11.091.418/0001-78 | H22: SP | I22: São Paulo | J22: 02739-000 | K22: VANDERLEY TRANSPORTES EIRELI | L22: 46218 | M22: D0 | N22: N | P22: CHEGADA DHL | Q22: 46213.862 | R22: 10/07/2026 20:42:18 - sex - TMSBENNER - Todas as filiais | S22: 254470950 | T22: Não | U22: 2026/651397-82-892978-1 | V22: PA - FILIAL SPG - GUARULHOS - SP | W22: AEMCE | Z22: PA - SCHADEK - PORTO FELIZ - SP | AA22: Distribuído | AB22: 429.33 | AC22: 1 | AD22: 1.398 | AE22: 35260760851417000190550010008929781223379963 | AF22: 46213.685 | AG22: 41594 | AI22: METALURGICA SCHADEK LTDA | AJ22: Transferência | AK22: 2026/651397-82 | AL22: 35260760851417000190550010008929781223379963 | AM22: No Prazo | AN22: 27 | AO22: Outbound | AP22: 60.851.417/0001-90 | AR22: 97 | AS22: 46213.829 | AU22: 60.851.417/0001-90 | AV22: SP | AW22: Porto Feliz | AX22: Carlos Magalhaes | AY22: 18547-216 | AZ22: Jardim Bela Vista | BA22: METALURGICA SCHADEK LTDA | BB22: Itaberaba | BC22: 35260700233065000187572110000415941000415942 | BE22: METALURGICA SCHADEK LTDA | BF22: 4 | BG22: Não | BI22: 46211 | BJ22: 02739-000 | BK22: PA - HUB CEL - SP - DOX 1000 | BL22: 0080790818 | BM22: 1.398 | BN22: 1.165 | BQ22: PA - FILIAL SPG - GUARULHOS - SP | BS22: Distribuído | BU22: Itaberaba,4516 | BW22: Em Elaboração | BY22: NÃO | CB22: CADASTRAR | CC22: CEL H | CD22: SPG | CE22: PA - FILIAL SPG - GUARULHOS - SP | CF22: SPG
A23: Rota 32 | B23: METALURGICA SCHADEK LTDA | C23: 894088 | D23: 1 | E23: Piqueri Com Distr De Auto Pecas Ltda | F23: - | G23: 60.672.441/0001-61 | H23: SP | I23: São Paulo | J23: 02912-000 | K23: VANDERLEY TRANSPORTES EIRELI | L23: 46218 | M23: D0 | N23: N | P23: CHEGADA DHL | Q23: 46213.862 | R23: 10/07/2026 20:42:18 - sex - TMSBENNER - Todas as filiais | S23: 254540776 | T23: Não | U23: 2026/651397-82-894088-1 | V23: PA - FILIAL SPG - GUARULHOS - SP | W23: AEMCE | Z23: PA - SCHADEK - PORTO FELIZ - SP | AA23: Distribuído | AB23: 1380.66 | AC23: 1 | AD23: 10.56 | AE23: 35260760851417000190550010008940881151440471 | AF23: 46213.687 | AG23: 41818 | AI23: METALURGICA SCHADEK LTDA | AJ23: Transferência | AK23: 2026/651397-82 | AL23: 35260760851417000190550010008940881151440471 | AM23: No Prazo | AN23: 29 | AO23: Outbound | AP23: 60.851.417/0001-90 | AR23: 97 | AS23: 46213.829 | AU23: 60.851.417/0001-90 | AV23: SP | AW23: Porto Feliz | AX23: Carlos Magalhaes | AY23: 18547-216 | AZ23: Jardim Bela Vista | BA23: METALURGICA SCHADEK LTDA | BB23: Casa Verde Baixa | BC23: 35260700233065000187572110000418181000418180 | BE23: METALURGICA SCHADEK LTDA | BF23: 4 | BG23: Não | BI23: 46212 | BJ23: 02912-000 | BK23: PA - HUB CEL - SP - DOX 1000 | BL23: 0080791788 | BM23: 10.56 | BN23: 8.8 | BQ23: PA - FILIAL SPG - GUARULHOS - SP | BS23: Distribuído | BU23: Coronel Bento Bicudo,767 | BW23: Em Elaboração | BY23: NÃO | CB23: CADASTRAR | CC23: CEL H | CD23: SPG | CE23: PA - FILIAL SPG - GUARULHOS - SP | CF23: SPG
A24: Rota 32 | B24: METALURGICA SCHADEK LTDA | C24: 894087 | D24: 1 | E24: Piqueri Com Distr De Auto Pecas Ltda | F24: - | G24: 60.672.441/0001-61 | H24: SP | I24: São Paulo | J24: 02912-000 | K24: VANDERLEY TRANSPORTES EIRELI | L24: 46218 | M24: D0 | N24: N | P24: CHEGADA DHL | Q24: 46213.967 | R24: 10/07/2026 23:14:39 - sex - TMSBENNER - Todas as filiais | S24: 254540796 | T24: Não | U24: 2026/651397-82-894087-1 | V24: PA - FILIAL SPG - GUARULHOS - SP | W24: AEMCE | Z24: PA - SCHADEK - PORTO FELIZ - SP | AA24: Distribuído | AB24: 1132.04 | AC24: 1 | AD24: 5.736 | AE24: 35260760851417000190550010008940871700630773 | AF24: 46213.806 | AG24: 41961 | AI24: METALURGICA SCHADEK LTDA | AJ24: Transferência | AK24: 2026/651397-82 | AL24: 35260760851417000190550010008940871700630773 | AM24: No Prazo | AN24: 29 | AO24: Outbound | AP24: 60.851.417/0001-90 | AR24: 97 | AS24: 46213.944 | AU24: 60.851.417/0001-90 | AV24: SP | AW24: Porto Feliz | AX24: Carlos Magalhaes | AY24: 18547-216 | AZ24: Jardim Bela Vista | BA24: METALURGICA SCHADEK LTDA | BB24: Casa Verde Baixa | BC24: 35260700233065000187572110000419611000419612 | BE24: METALURGICA SCHADEK LTDA | BF24: 4 | BG24: Não | BI24: 46212 | BJ24: 02912-000 | BK24: PA - HUB CEL - SP - DOX 1000 | BL24: 0080789847 | BM24: 5.736 | BN24: 4.78 | BQ24: PA - FILIAL SPG - GUARULHOS - SP | BS24: Distribuído | BU24: Coronel Bento Bicudo,767 | BW24: Em Elaboração | BY24: NÃO | CB24: CADASTRAR | CC24: CEL H | CD24: SPG | CE24: PA - FILIAL SPG - GUARULHOS - SP | CF24: SPG
A25: Rota 26 | B25: METALURGICA SCHADEK LTDA | C25: 894084 | D25: 1 | E25: KOGA KOGA CIA LTDA KOGA KOGA | F25: - | G25: 61.256.996/0004-38 | H25: SP | I25: São Paulo | J25: 03191-160 | K25: VANDERLEY TRANSPORTES EIRELI | L25: 46218 | M25: D0 | N25: N | P25: CHEGADA DHL | Q25: 46213.967 | R25: 10/07/2026 23:14:31 - sex - TMSBENNER - Todas as filiais | S25: 254540742 | T25: Não | U25: 2026/651397-82-894084-1 | V25: PA - FILIAL SPG - GUARULHOS - SP | W25: AEMCE | Z25: PA - SCHADEK - PORTO FELIZ - SP | AA25: Distribuído | AB25: 284.97 | AC25: 1 | AD25: 1.188 | AE25: 35260760851417000190550010008940841238796880 | AF25: 46213.806 | AG25: 41924 | AI25: METALURGICA SCHADEK LTDA | AJ25: Transferência | AK25: 2026/651397-82 | AL25: 35260760851417000190550010008940841238796880 | AM25: No Prazo | AN25: 31 | AO25: Outbound | AP25: 60.851.417/0001-90 | AR25: 97 | AS25: 46213.944 | AU25: 60.851.417/0001-90 | AV25: SP | AW25: Porto Feliz | AX25: Carlos Magalhaes | AY25: 18547-216 | AZ25: Jardim Bela Vista | BA25: METALURGICA SCHADEK LTDA | BB25: Vila Canero | BC25: 35260700233065000187572110000419241000419244 | BE25: METALURGICA SCHADEK LTDA | BF25: 4 | BG25: Não | BI25: 46212 | BJ25: 03191-160 | BK25: PA - HUB CEL - SP - DOX 1000 | BL25: 0080793220 | BM25: 1.188 | BN25: 0.99 | BQ25: PA - FILIAL SPG - GUARULHOS - SP | BS25: Distribuído | BU25: Amapa,161 | BW25: Em Elaboração | BY25: NÃO | CB25: CADASTRAR | CC25: CEL H | CD25: SPG | CE25: PA - FILIAL SPG - GUARULHOS - SP | CF25: SPG
A26: Rota 26 | B26: METALURGICA SCHADEK LTDA | C26: 894082 | D26: 1 | E26: KOGA KOGA CIA LTDA KOGA KOGA | F26: - | G26: 61.256.996/0004-38 | H26: SP | I26: São Paulo | J26: 03191-160 | K26: VANDERLEY TRANSPORTES EIRELI | L26: 46218 | M26: D0 | N26: N | P26: CHEGADA DHL | Q26: 46213.862 | R26: 10/07/2026 20:42:21 - sex - TMSBENNER - Todas as filiais | S26: 254540759 | T26: Não | U26: 2026/651397-82-894082-1 | V26: PA - FILIAL SPG - GUARULHOS - SP | W26: AEMCE | Z26: PA - SCHADEK - PORTO FELIZ - SP | AA26: Distribuído | AB26: 80.33 | AC26: 1 | AD26: 0.6792 | AE26: 35260760851417000190550010008940821451904216 | AF26: 46213.687 | AG26: 41815 | AI26: METALURGICA SCHADEK LTDA | AJ26: Transferência | AK26: 2026/651397-82 | AL26: 35260760851417000190550010008940821451904216 | AM26: No Prazo | AN26: 31 | AO26: Outbound | AP26: 60.851.417/0001-90 | AR26: 97 | AS26: 46213.829 | AU26: 60.851.417/0001-90 | AV26: SP | AW26: Porto Feliz | AX26: Carlos Magalhaes | AY26: 18547-216 | AZ26: Jardim Bela Vista | BA26: METALURGICA SCHADEK LTDA | BB26: Vila Canero | BC26: 35260700233065000187572110000418151000418154 | BE26: METALURGICA SCHADEK LTDA | BF26: 4 | BG26: Não | BI26: 46212 | BJ26: 03191-160 | BK26: PA - HUB CEL - SP - DOX 1000 | BL26: 0080791866 | BM26: 0.6792 | BN26: 0.566 | BQ26: PA - FILIAL SPG - GUARULHOS - SP | BS26: Distribuído | BU26: Amapa,161 | BW26: Em Elaboração | BY26: NÃO | CB26: CADASTRAR | CC26: CEL H | CD26: SPG | CE26: PA - FILIAL SPG - GUARULHOS - SP | CF26: SPG
A27: Rota 26 | B27: METALURGICA SCHADEK LTDA | C27: 894083 | D27: 1 | E27: KOGA KOGA CIA LTDA KOGA KOGA | F27: - | G27: 61.256.996/0004-38 | H27: SP | I27: São Paulo | J27: 03191-160 | K27: VANDERLEY TRANSPORTES EIRELI | L27: 46218 | M27: D0 | N27: N | P27: CHEGADA DHL | Q27: 46213.967 | R27: 10/07/2026 23:14:31 - sex - TMSBENNER - Todas as filiais | S27: 254540764 | T27: Não | U27: 2026/651397-82-894083-1 | V27: PA - FILIAL SPG - GUARULHOS - SP | W27: AEMCE | Z27: PA - SCHADEK - PORTO FELIZ - SP | AA27: Distribuído | AB27: 307.11 | AC27: 1 | AD27: 1.098 | AE27: 35260760851417000190550010008940831605536901 | AF27: 46213.806 | AG27: 41924 | AI27: METALURGICA SCHADEK LTDA | AJ27: Transferência | AK27: 2026/651397-82 | AL27: 35260760851417000190550010008940831605536901 | AM27: No Prazo | AN27: 31 | AO27: Outbound | AP27: 60.851.417/0001-90 | AR27: 97 | AS27: 46213.944 | AU27: 60.851.417/0001-90 | AV27: SP | AW27: Porto Feliz | AX27: Carlos Magalhaes | AY27: 18547-216 | AZ27: Jardim Bela Vista | BA27: METALURGICA SCHADEK LTDA | BB27: Vila Canero | BC27: 35260700233065000187572110000419241000419244 | BE27: METALURGICA SCHADEK LTDA | BF27: 4 | BG27: Não | BI27: 46212 | BJ27: 03191-160 | BK27: PA - HUB CEL - SP - DOX 1000 | BL27: 0080792783 | BM27: 1.098 | BN27: 0.915 | BQ27: PA - FILIAL SPG - GUARULHOS - SP | BS27: Distribuído | BU27: Amapa,161 | BW27: Em Elaboração | BY27: NÃO | CB27: CADASTRAR | CC27: CEL H | CD27: SPG | CE27: PA - FILIAL SPG - GUARULHOS - SP | CF27: SPG
A28: Rota 31 | B28: METALURGICA SCHADEK LTDA | C28: 893142 | D28: 1 | E28: Comdip Comercial Distribuidora De P | F28: - | G28: 68.647.312/0002-06 | H28: SP | I28: São Paulo | J28: 05033-002 | K28: VANDERLEY TRANSPORTES EIRELI | L28: 46218 | M28: D0 | N28: N | P28: CHEGADA DHL | Q28: 46213.862 | R28: 10/07/2026 20:42:20 - sex - TMSBENNER - Todas as filiais | S28: 254471269 | T28: Não | U28: 2026/651397-82-893142-1 | V28: PA - FILIAL SPG - GUARULHOS - SP | W28: AEMCE | Z28: PA - SCHADEK - PORTO FELIZ - SP | AA28: Distribuído | AB28: 1149.7 | AC28: 2 | AD28: 22.3248 | AE28: 35260760851417000190550010008931421112056552 | AF28: 46213.685 | AG28: 41619 | AI28: METALURGICA SCHADEK LTDA | AJ28: Transferência | AK28: 2026/651397-82 | AL28: 35260760851417000190550010008931421112056552 | AM28: No Prazo | AN28: 50 | AO28: Outbound | AP28: 60.851.417/0001-90 | AR28: 97 | AS28: 46213.829 | AU28: 60.851.417/0001-90 | AV28: SP | AW28: Porto Feliz | AX28: Carlos Magalhaes | AY28: 18547-216 | AZ28: Jardim Bela Vista | BA28: METALURGICA SCHADEK LTDA | BB28: Água Branca | BC28: 35260700233065000187572110000416191000416192 | BE28: METALURGICA SCHADEK LTDA | BF28: 4 | BG28: Não | BI28: 46211 | BJ28: 05033-002 | BK28: PA - HUB CEL - SP - DOX 1000 | BL28: 0080790838 | BM28: 22.3248 | BN28: 18.604 | BQ28: PA - FILIAL SPG - GUARULHOS - SP | BS28: Distribuído | BU28: Guaicurus,1317 | BW28: Em Elaboração | BY28: NÃO | CB28: CADASTRAR | CC28: CEL H | CD28: SPG | CE28: PA - FILIAL SPG - GUARULHOS - SP | CF28: SPG
